Traceback (most recent call last):
  File "/home/tonu/.local/share/virtualenvs/dashboard_invest-5AWLHTjn/lib/python3.11/site-packages/pandas/core/indexes/base.py", line 3802, in get_loc
    return self._engine.get_loc(casted_key)
           ^^^^^^^^^^^^^^^^^^^^^^^^^^^^^^^^
  File "pandas/_libs/index.pyx", line 138, in pandas._libs.index.IndexEngine.get_loc
  File "pandas/_libs/index.pyx", line 165, in pandas._libs.index.IndexEngine.get_loc
  File "pandas/_libs/hashtable_class_helper.pxi", line 5745, in pandas._libs.hashtable.PyObjectHashTable.get_item
  File "pandas/_libs/hashtable_class_helper.pxi", line 5753, in pandas._libs.hashtable.PyObjectHashTable.get_item
KeyError: 'Total Value'

The above exception was the direct cause of the following exception:

Traceback (most recent call last):
  File "/tmp/ipykernel_256819/1712138456.py", line 330, in wrapper
    result = func(ddf)
             ^^^^^^^^^
  File "/tmp/ipykernel_256819/1386671443.py", line 345, in investments_script
    return (df_plot[a] / df_plot[a].sum() * 100).round(2)
            ~~~~~~~^^^
  File "/home/tonu/.local/share/virtualenvs/dashboard_invest-5AWLHTjn/lib/python3.11/site-packages/pandas/core/frame.py", line 3807, in __getitem__
    indexer = self.columns.get_loc(key)
              ^^^^^^^^^^^^^^^^^^^^^^^^^
  File "/home/tonu/.local/share/virtualenvs/dashboard_invest-5AWLHTjn/lib/python3.11/site-packages/pandas/core/indexes/base.py", line 3804, in get_loc
    raise KeyError(key) from err
KeyError: 'Total Value'
