Traceback (most recent call last):
  File "/tmp/ipykernel_719199/4156802437.py", line 31, in wrapper
    raise ValueError
ValueError
